<?xml version='1.0'?>
<sdf version='1.6'>
  <model name='fast_ver2'>

<!--
    <joint name="world_to_body" type="fixed">
        <parent>world</parent>
        <child>body</child>
        <pose>0 0 0 0 0 0</pose>
    </joint> -->

    <link name="body">
        <self_collide>1</self_collide>
        <inertial>
          <inertia> ixx=0.0001 ixy=0.000  ixz=0.000  
         iyy=0.0001 iyz=0.000
         izz=0.0001
         </inertia>
            <mass>2.915</mass>
        </inertial>
        <visual name="visual">
            <geometry>
                 <mesh>
                    <uri>model://fast_ver2/meshes/collision/body.dae</uri>
                    <scale>1 1 1</scale>
                </mesh>
            </geometry>
            <material>
                <script>
                    <uri>file://media/materials/scripts/gazebo.material</uri>
                    <name>Gazebo/Red</name>
                </script>
            </material>
        </visual>
        <collision name='collision'>
            <geometry>
                 <mesh>
                    <uri>model://fast_ver2/meshes/collision/body.dae</uri>
                    <scale>1 1 1</scale>
                </mesh>
            </geometry>
            <surface>
          <friction>
            <ode>
              <mu>0.05</mu>
              <mu2>0.05</mu2>
            </ode>
          </friction>
        </surface>
        </collision>
    </link>

   


    <joint name="body_to_power_top" type="revolute">
        <pose>0 0.02 0.03 0 0 0</pose>
        <parent>body</parent>
        <child>power_top</child>
        <axis>
            <xyz>1 0 0</xyz>
        </axis>
    </joint>

    <joint name="body_to_fixed_top" type="revolute">
        <pose>0 0.05 0.03 0 0 0</pose>
        <parent>fixed_top</parent>
        <child>body</child>
        <axis>
            <xyz>1 0 0</xyz>

        </axis>
    </joint>

    

    <joint name="body_to_fixed_bottom" type="revolute">
        <pose>0 0.035 0.01 0 0 0</pose>
        <parent>body</parent>
        <child>fixed_bottom</child>
        <axis>
            <xyz>1 0 0</xyz>

        </axis>
    </joint>

    <link name="power_top">
        <self_collide>1</self_collide>
        <inertial>
 <inertia> ixx=0.0001 ixy=0.000  ixz=0.000  
         iyy=0.0001 iyz=0.000
         izz=0.0001
         </inertia>
            <mass>2.915</mass>
        </inertial>
        <visual name="visual">
            <geometry>
                <mesh>
                    <uri>model://fast_ver2/meshes/collision/power_top.dae</uri>
                    <scale>1 1 1</scale>
                </mesh>
            </geometry>
        </visual>
        <collision name='collision'>
            <geometry>
                <mesh>
                    <uri>model://fast_ver2/meshes/collision/power_top.dae</uri>
                    <scale>1 1 1</scale>
                </mesh>
            </geometry>
            <surface>
                <friction>
                    <ode>
                        <mu>0.05</mu>
                        <mu2>0.05</mu2>
                    </ode>
                </friction>
            </surface>
        </collision>
    </link>

    <joint name="power_top_to_connector_top" type="revolute">
        <pose>0 0.03 0.035 0 0 0</pose>
        <parent>power_top</parent>
        <child>connector_top</child>
        <axis>
            <xyz>1 0 0</xyz>
 
        </axis>
    </joint>

    <link name="connector_top">
        <self_collide>1</self_collide>
        <inertial>
          <inertia> ixx=0.0001 ixy=0.000  ixz=0.000  
         iyy=0.0001 iyz=0.000
         izz=0.0001
         </inertia>
            <mass>2.915</mass>
        </inertial>
        <visual name="visual">
            <geometry>
                <mesh>
                    <uri>model://fast_ver2/meshes/collision/connector_top.dae</uri>
                    <scale>1 1 1</scale>
                </mesh>
            </geometry>
        </visual>
        <collision name='collision'>
            <geometry>
                <mesh>
                    <uri>model://fast_ver2/meshes/collision/connector_top.dae</uri>
                    <scale>1 1 1</scale>
                </mesh>
            </geometry>
            <surface>
                <friction>
                    <ode>
                        <mu>0.05</mu>
                        <mu2>0.05</mu2>
                    </ode>
                </friction>
            </surface>
        </collision>
    </link>

    <joint name="connector_top_to_arm" type="revolute">
        <pose>0 0.05 0.055 0 0 0</pose>
        <parent>connector_top</parent>
        <child>connector_arm</child>
        <axis>
            <xyz>1 0 0</xyz>
 
        </axis>
    </joint>

    <link name="connector_arm">
        <self_collide>1</self_collide>
        <inertial>
         <inertia> ixx=0.0001 ixy=0.000  ixz=0.000  
         iyy=0.0001 iyz=0.000
         izz=0.0001
         </inertia>
            <mass>2.915</mass>
        </inertial>
        <visual name="visual">
            <geometry>
                <mesh>
                    <uri>model://fast_ver2/meshes/collision/connector_arm.dae</uri>
                    <scale>1 1 1</scale>
                </mesh>
            </geometry>
        </visual>
        <collision name='collision'>
            <geometry>
                <mesh>
                    <uri>model://fast_ver2/meshes/collision/connector_arm.dae</uri>
                    <scale>1 1 1</scale>
                </mesh>
            </geometry>
            <surface>
                <friction>
                    <ode>
                        <mu>0.05</mu>
                        <mu2>0.05</mu2>
                    </ode>
                </friction>
            </surface>
        </collision>
    </link>
   
   <joint name="connector_top_to_fixed_top" type="revolute">
        <pose>0 0.05 0.055 0 0 0</pose>
        <parent>connector_top</parent>
        <child>fixed_top</child>
        <axis>
            <xyz>1 0 0</xyz>
        </axis>
    </joint>

    <link name="fixed_top">
        <self_collide>1</self_collide>
        <inertial>
           <inertia> ixx=0.0001 ixy=0.000  ixz=0.000  
         iyy=0.0001 iyz=0.000
         izz=0.0001
         </inertia>
            <mass>2.915</mass>
        </inertial>
        <visual name="visual">
            <geometry>
                <mesh>
                    <uri>model://fast_ver2/meshes/collision/fixed_top.dae</uri>
                    <scale>1 1 1</scale>
                </mesh>
            </geometry>
        </visual>
        <collision name='collision'>
            <geometry>
                <mesh>
                    <uri>model://fast_ver2/meshes/collision/fixed_top.dae</uri>
                    <scale>1 1 1</scale>
                </mesh>
            </geometry>
            <surface>
                <friction>
                    <ode>
                        <mu>0.05</mu>
                        <mu2>0.05</mu2>
                    </ode>
                </friction>
            </surface>
        </collision>
    </link>

    <joint name="connector_arm_to_hanging_arm" type="revolute">
        <pose>0 0.085 0.04 0 0 0</pose>
        <parent>connector_arm</parent>
        <child>hanging_arm</child>
        <axis>
            <xyz>1 0 0</xyz>

        </axis>
    </joint>

    <link name="hanging_arm">
        <self_collide>1</self_collide>
        <inertial>
          <inertia> ixx=0.0001 ixy=0.000  ixz=0.000  
         iyy=0.0001 iyz=0.000
         izz=0.0001
         </inertia>
            <mass>2.915</mass>
        </inertial>
        <visual name="visual">
            <geometry>
                <mesh>
                    <uri>model://fast_ver2/meshes/collision/hanging_arm.dae</uri>
                    <scale>1 1 1</scale>
                </mesh>
            </geometry>
            <material>
                <script>
                    <uri>file://media/materials/scripts/gazebo.material</uri>
                    <name>Gazebo/Yellow</name>
                </script>
            </material>
        </visual>
        <collision name='collision'>
            <geometry>
                <mesh>
                    <uri>model://fast_ver2/meshes/collision/hanging_arm.dae</uri>
                    <scale>1 1 1</scale>
                </mesh>
            </geometry>
            <surface>
                <friction>
                    <ode>
                        <mu>0.05</mu>
                        <mu2>0.05</mu2>
                    </ode>
                </friction>
            </surface>
        </collision>
    </link>

     <joint name="hanging_arm_to_fixed_bottom" type="revolute">
        <pose>0 0.065 0.01 0 0 0</pose>
        <parent>fixed_bottom</parent>
        <child>hanging_arm</child>
        <axis>
            <xyz>1 0 0</xyz>

        </axis>
    </joint>

    <link name="fixed_bottom">
        <self_collide>1</self_collide>
        <inertial>
          <inertia> ixx=0.0001 ixy=0.000  ixz=0.000  
         iyy=0.0001 iyz=0.000
         izz=0.0001
         </inertia>
            <mass>2.915</mass>
        </inertial>
        <visual name="visual">
            <geometry>
                <mesh>
                    <uri>model://fast_ver2/meshes/collision/fixed_bottom.dae</uri>
                    <scale>1 1 1</scale>
                </mesh>
            </geometry>
        </visual>
        <collision name='collision'>
            <geometry>
                <mesh>
                    <uri>model://fast_ver2/meshes/collision/fixed_bottom.dae</uri>
                    <scale>1 1 1</scale>
                </mesh>
            </geometry>
            <surface>
                <friction>
                    <ode>
                        <mu>0.05</mu>
                        <mu2>0.05</mu2>
                    </ode>
                </friction>
            </surface>
        </collision>
    </link>

     <joint name="fixed_bottom_to_connector_bottom" type="revolute">
        <pose>0 0.035 0.03 0 0 0</pose>
        <parent>connector_bottom</parent>
        <child>fixed_bottom</child>
        <axis>
            <xyz>1 0 0</xyz>
        </axis>
    </joint>

    <link name="connector_bottom">
        <self_collide>1</self_collide>
        <inertial>
          <inertia> ixx=0.0001 ixy=0.000  ixz=0.000  
         iyy=0.0001 iyz=0.000
         izz=0.0001
         </inertia>
            <mass>2.915</mass>
        </inertial>
        <visual name="visual">
            <geometry>
                <mesh>
                    <uri>model://fast_ver2/meshes/collision/connector_bottom.dae</uri>
                    <scale>1 1 1</scale>
                </mesh>
            </geometry>
        </visual>
        <collision name='collision'>
            <geometry>
                <mesh>
                    <uri>model://fast_ver2/meshes/collision/connector_bottom.dae</uri>
                    <scale>1 1 1</scale>
                </mesh>
            </geometry>
            <surface>
                <friction>
                    <ode>
                        <mu>0.05</mu>
                        <mu2>0.05</mu2>
                    </ode>
                </friction>
            </surface>
        </collision>
    </link>

     <joint name="connector_bottom_to_power_bottom" type="revolute">
        <pose>0 0 0.01 0 0 0</pose>
        <parent>power_bottom</parent>
        <child>connector_bottom</child>
        <axis>
            <xyz>1 0 0</xyz>
        </axis>
    </joint>

    <link name="power_bottom">
        <self_collide>1</self_collide>
        <inertial>
             <inertia> ixx=0.0001 ixy=0.000  ixz=0.000  
         iyy=0.0001 iyz=0.000
         izz=0.0001
         </inertia>
            <mass>2.915</mass>
        </inertial>
        <visual name="visual">
            <geometry>
                <mesh>
                    <uri>model://fast_ver2/meshes/collision/power_bottom.dae</uri>
                    <scale>1 1 1</scale>
                </mesh>
            </geometry>
        </visual>
        <collision name='collision'>
            <geometry>
                <mesh>
                    <uri>model://fast_ver2/meshes/collision/power_bottom.dae</uri>
                    <scale>1 1 1</scale>
                </mesh>
            </geometry>
            <surface>
                <friction>
                    <ode>
                        <mu>0.05</mu>
                        <mu2>0.05</mu2>
                    </ode>
                </friction>
            </surface>
        </collision>
    </link>

    <joint name="body_to_power_bottom" type="revolute">
        <pose>0 0 0.02 0 0 0</pose>
        <parent>body</parent>
        <child>power_bottom</child>
        <axis>
            <xyz>1 0 0</xyz>
        </axis>
    </joint>

<plugin name="gazebo_ros_control" filename="libgazebo_ros_control.so">
      <robotNamespace>fast_ver2</robotNamespace>
      <robotSimType>gazebo_ros_control/DefaultRobotHWSim</robotSimType>
      <legacyModeNS>true</legacyModeNS>
    </plugin>

    <plugin name="joint_state_publisher" filename="libgazebo_ros_joint_state_publisher.so">
        <robotNamespace>fast_ver2</robotNamespace>
        <jointName>body_to_power_bottom, body_to_power_top</jointName>
    </plugin>

  </model>
</sdf>