<?xml version='1.0'?>
<sdf version='1.6'>
  <model name='fast_ver1'>



    <link name="base">
        <gravity>0</gravity>
        <self_collide>1</self_collide>
        <pose>-0.005 0 0 0 0 0</pose>
        <visual name="visual">
            <geometry>
                <box>
                    <size>0.000001 0.04 0.0125</size>
                </box>
            </geometry>
        </visual>
        <collision name='collision'>
            <geometry>
                <box>
                    <size>0.000001 0.04 0.0125</size>
                </box>
            </geometry>
            <surface>
                <friction>
                    <ode>
                        <mu>0.05</mu>
                        <mu2>0.05</mu2>
                    </ode>
                </friction>
            </surface>
        </collision>
    </link>

    <link name="fixed_link">
            <gravity>0</gravity>
        <pose>0 0 0 0 0 0</pose>
    </link>
   
    <joint name="fixed_to_base" type="fixed">
        <pose>0 0 0 0 0 0</pose>
        <parent>fixed_link</parent>
        <child>base</child>
    </joint>


    <joint name="base_to_power_top" type="revolute">
        <pose>0 0 0.02 0 0 0</pose>
        <parent>base</parent>
        <child>power_top</child>
        <axis>
            <xyz>1 0 0</xyz>
        </axis>
    </joint>

    <joint name="base_to_fixed_top" type="revolute">
        <pose>0 0.04 0.025 0 0 0</pose>
        <parent>fixed_top</parent>
        <child>base</child>
        <axis>
            <xyz>1 0 0</xyz>

        </axis>
    </joint>

    <joint name="base_to_power_bottom" type="revolute">
        <pose>0 0 0.01 0 0 0</pose>
        <parent>power_bottom</parent>
        <child>base</child>
        <axis>
            <xyz>1 0 0</xyz>

        </axis>
    </joint>

    <joint name="base_to_fixed_top" type="revolute">
        <pose>0 0.04 0 0 0 0</pose>
        <parent>fixed_bottom</parent>
        <child>base</child>
        <axis>
            <xyz>1 0 0</xyz>

        </axis>
    </joint>

    <link name="power_top">
        <self_collide>1</self_collide>
        <gravity>0</gravity>
        <visual name="visual">
            <geometry>
                <mesh>
                    <uri>model://fast_ver1/meshes/power_top.dae</uri>
                    <scale>1 1 1</scale>
                </mesh>
            </geometry>
        </visual>
        <collision name='collision'>
            <geometry>
                <mesh>
                    <uri>model://fast_ver1/meshes/power_top.dae</uri>
                    <scale>1 1 1</scale>
                </mesh>
            </geometry>
            <surface>
                <friction>
                    <ode>
                        <mu>0.05</mu>
                        <mu2>0.05</mu2>
                    </ode>
                </friction>
            </surface>
            
        </collision>
    </link>

    <joint name="power_top_to_connector_top" type="revolute">
        <pose>0 0 0.03 0 0 0</pose>
        <parent>power_top</parent>
        <child>connector_top</child>
        <axis>
            <xyz>1 0 0</xyz>
 
        </axis>
    </joint>

    <link name="connector_top">
        <self_collide>1</self_collide>
        <gravity>0</gravity>
        <visual name="visual">
            <geometry>
                <mesh>
                    <uri>model://fast_ver1/meshes/connector_top.dae</uri>
                    <scale>1 1 1</scale>
                </mesh>
            </geometry>
        </visual>
        <collision name='collision'>
            <geometry>
                <mesh>
                    <uri>model://fast_ver1/meshes/connector_top.dae</uri>
                    <scale>1 1 1</scale>
                </mesh>
            </geometry>
            <surface>
                <friction>
                    <ode>
                        <mu>0.05</mu>
                        <mu2>0.05</mu2>
                    </ode>
                </friction>
            </surface>
        </collision>
    </link>

    <joint name="connector_top_to_arm" type="revolute">
        <pose>0 0.04 0.05 0 0 0</pose>
        <parent>connector_top</parent>
        <child>connector_arm</child>
        <axis>
            <xyz>1 0 0</xyz>
 
        </axis>
    </joint>

    <link name="connector_arm">
        <self_collide>1</self_collide>
        <gravity>0</gravity>
        <visual name="visual">
            <geometry>
                <mesh>
                    <uri>model://fast_ver1/meshes/connector_arm.dae</uri>
                    <scale>1 1 1</scale>
                </mesh>
            </geometry>
        </visual>
        <collision name='collision'>
            <geometry>
                <mesh>
                    <uri>model://fast_ver1/meshes/connector_arm.dae</uri>
                    <scale>1 1 1</scale>
                </mesh>
            </geometry>
            <surface>
                <friction>
                    <ode>
                        <mu>0.05</mu>
                        <mu2>0.05</mu2>
                    </ode>
                </friction>
            </surface>
        </collision>
    </link>
   
   <joint name="connector_top_to_fixed_top" type="revolute">
        <pose>0 0.04 0.05 0 0 0</pose>
        <parent>connector_top</parent>
        <child>fixed_top</child>
        <axis>
            <xyz>1 0 0</xyz>
 
        </axis>
    </joint>

    <link name="fixed_top">
        <self_collide>1</self_collide>
        <gravity>0</gravity>
        <visual name="visual">
            <geometry>
                <mesh>
                    <uri>model://fast_ver1/meshes/fixed_top.dae</uri>
                    <scale>1 1 1</scale>
                </mesh>
            </geometry>
        </visual>
        <collision name='collision'>
            <geometry>
                <mesh>
                    <uri>model://fast_ver1/meshes/fixed_top.dae</uri>
                    <scale>1 1 1</scale>
                </mesh>
            </geometry>
            <surface>
                <friction>
                    <ode>
                        <mu>0.05</mu>
                        <mu2>0.05</mu2>
                    </ode>
                </friction>
            </surface>
        </collision>
    </link>

    <joint name="connector_arm_to_hanging_arm" type="revolute">
        <pose>0 0.075 0.04 0 0 0</pose>
        <parent>connector_arm</parent>
        <child>hanging_arm</child>
        <axis>
            <xyz>1 0 0</xyz>

        </axis>
    </joint>

    <link name="hanging_arm">
        <self_collide>1</self_collide>
        <gravity>0</gravity>
        <visual name="visual">
            <geometry>
                <mesh>
                    <uri>model://fast_ver1/meshes/hanging_arm.dae</uri>
                    <scale>1 1 1</scale>
                </mesh>
            </geometry>
        </visual>
        <collision name='collision'>
            <geometry>
                <mesh>
                    <uri>model://fast_ver1/meshes/hanging_arm.dae</uri>
                    <scale>1 1 1</scale>
                </mesh>
            </geometry>
            <surface>
                <friction>
                    <ode>
                        <mu>0.05</mu>
                        <mu2>0.05</mu2>
                    </ode>
                </friction>
            </surface>
        </collision>
    </link>

     <joint name="hanging_arm_to_fixed_bottom" type="revolute">
        <pose>0 0.065 0 0 0 0</pose>
        <parent>hanging_arm</parent>
        <child>fixed_bottom</child>
        <axis>
            <xyz>1 0 0</xyz>

        </axis>
    </joint>

    <link name="fixed_bottom">
        <self_collide>1</self_collide>
        <gravity>0</gravity>
        <visual name="visual">
            <geometry>
                <mesh>
                    <uri>model://fast_ver1/meshes/fixed_bottom.dae</uri>
                    <scale>1 1 1</scale>
                </mesh>
            </geometry>
        </visual>
        <collision name='collision'>
            <geometry>
                <mesh>
                    <uri>model://fast_ver1/meshes/fixed_bottom.dae</uri>
                    <scale>1 1 1</scale>
                </mesh>
            </geometry>
            <surface>
                <friction>
                    <ode>
                        <mu>0.05</mu>
                        <mu2>0.05</mu2>
                    </ode>
                </friction>
            </surface>
        </collision>
    </link>

     <joint name="fixed_bottom_to_connector_bottom" type="revolute">
        <pose>0 0.04 0.015 0 0 0</pose>
        <parent>fixed_bottom</parent>
        <child>connector_bottom</child>
        <axis>
            <xyz>1 0 0</xyz>

        </axis>
    </joint>

    <link name="connector_bottom">
        <self_collide>1</self_collide>
        <gravity>0</gravity>
        <visual name="visual">
            <geometry>
                <mesh>
                    <uri>model://fast_ver1/meshes/connector_bottom.dae</uri>
                    <scale>1 1 1</scale>
                </mesh>
            </geometry>
        </visual>
        <collision name='collision'>
            <geometry>
                <mesh>
                    <uri>model://fast_ver1/meshes/connector_bottom.dae</uri>
                    <scale>1 1 1</scale>
                </mesh>
            </geometry>
            <surface>
                <friction>
                    <ode>
                        <mu>0.05</mu>
                        <mu2>0.05</mu2>
                    </ode>
                </friction>
            </surface>
        </collision>
    </link>

     <joint name="connector_bottom_to_power_bottom" type="revolute">
        <pose>0 0 0 0 0 0</pose>
        <parent>connector_bottom</parent>
        <child>power_bottom</child>
        <axis>
            <xyz>1 0 0</xyz>
  
        </axis>
    </joint>

    <link name="power_bottom">
        <self_collide>1</self_collide>
        <gravity>0</gravity>
        <visual name="visual">
            <geometry>
                <mesh>
                    <uri>model://fast_ver1/meshes/power_bottom.dae</uri>
                    <scale>1 1 1</scale>
                </mesh>
            </geometry>
        </visual>
        <collision name='collision'>
            <geometry>
                <mesh>
                    <uri>model://fast_ver1/meshes/power_bottom.dae</uri>
                    <scale>1 1 1</scale>
                </mesh>
            </geometry>
            <surface>
                <friction>
                    <ode>
                        <mu>0.05</mu>
                        <mu2>0.05</mu2>
                    </ode>
                </friction>
            </surface>
        </collision>
    </link>

    
  </model>
</sdf>